<?xml version="1.0" ?>
<!-- =================================================================================== -->
<!-- |    This document was autogenerated by xacro from roboarm.xacro                  | -->
<!-- |    EDITING THIS FILE BY HAND IS NOT RECOMMENDED                                 | -->
<!-- =================================================================================== -->
<robot name="roboarm">
  <link name="base_link">
    <visual>
      <origin rpy="1.571 0 0" xyz="-60 60 0"/>
      <geometry>
        <mesh filename="file:///home/andrew/roboarm/rviz2_ws/src/roboarm/install/roboarm/share/roboarm/meshes/Base.STL"/>
      </geometry>
    </visual>
    <collision>
      <origin rpy="1.571 0 0" xyz="-60 60 0"/>
      <geometry>
        <mesh filename="file:///home/andrew/roboarm/rviz2_ws/src/roboarm/install/roboarm/share/roboarm/meshes/Base.STL"/>
      </geometry>
    </collision>
  </link>
  <joint name="base_link__waist_link" type="revolute">
    <axis xyz="0 0 1"/>
    <limit effort="1000.0" lower="0" upper="3.14159" velocity="0.5"/>
    <origin rpy="0 0 0" xyz="0 0 57"/>
    <parent link="base_link"/>
    <child link="waist_link"/>
  </joint>
  <link name="waist_link">
    <visual>
      <origin rpy="1.571 0 0" xyz="-48.5 48.5 0"/>
      <geometry>
        <mesh filename="file:///home/andrew/roboarm/rviz2_ws/src/roboarm/install/roboarm/share/roboarm/meshes/Waist.STL"/>
      </geometry>
    </visual>
    <collision>
      <origin rpy="1.571 0 0" xyz="-48.5 48.5 0"/>
      <geometry>
        <mesh filename="file:///home/andrew/roboarm/rviz2_ws/src/roboarm/install/roboarm/share/roboarm/meshes/Waist.STL"/>
      </geometry>
    </collision>
  </link>
  <joint name="waist_link__arm1_link" type="revolute">
    <axis xyz="1 0 0"/>
    <limit effort="1000.0" lower="0" upper="3.14159" velocity="0.5"/>
    <origin rpy="0 0 0" xyz="-3 14 40"/>
    <parent link="waist_link"/>
    <child link="arm1_link"/>
  </joint>
  <link name="arm1_link">
    <visual>
      <origin rpy="1.571 1.571 1.571" xyz="0 -25.75 28.25"/>
      <geometry>
        <mesh filename="file:///home/andrew/roboarm/rviz2_ws/src/roboarm/install/roboarm/share/roboarm/meshes/Arm01.STL"/>
      </geometry>
    </visual>
    <collision>
      <origin rpy="1.571 1.571 1.571" xyz="0 -25.75 28.25"/>
      <geometry>
        <mesh filename="file:///home/andrew/roboarm/rviz2_ws/src/roboarm/install/roboarm/share/roboarm/meshes/Arm01.STL"/>
      </geometry>
    </collision>
  </link>
  <joint name="arm1_link__arm2_link" type="revolute">
    <axis xyz="1 0 0"/>
    <limit effort="1000.0" lower="0" upper="3.14159" velocity="0.5"/>
    <origin rpy="-1.571 0 0" xyz="0 120 0"/>
    <parent link="arm1_link"/>
    <child link="arm2_link"/>
  </joint>
  <link name="arm2_link">
    <visual>
      <origin rpy="0 4.7124 0" xyz="6 -25 -19.5"/>
      <geometry>
        <mesh filename="file:///home/andrew/roboarm/rviz2_ws/src/roboarm/install/roboarm/share/roboarm/meshes/Arm02v3.STL"/>
      </geometry>
    </visual>
    <collision>
      <origin rpy="0 4.7124 0" xyz="6 -25 -19.5"/>
      <geometry>
        <mesh filename="file:///home/andrew/roboarm/rviz2_ws/src/roboarm/install/roboarm/share/roboarm/meshes/Arm02v3.STL"/>
      </geometry>
    </collision>
  </link>
  <joint name="arm2_link__arm3_link" type="revolute">
    <axis xyz="0 1 0"/>
    <limit effort="1000.0" lower="0" upper="3.14159" velocity="0.5"/>
    <origin rpy="0 -3.14159 0" xyz="-8 90 -6"/>
    <parent link="arm2_link"/>
    <child link="arm3_link"/>
  </joint>
  <link name="arm3_link">
    <visual>
      <origin rpy="0 0 0" xyz="-11.5 1 -13.75"/>
      <geometry>
        <mesh filename="file:///home/andrew/roboarm/rviz2_ws/src/roboarm/install/roboarm/share/roboarm/meshes/Arm03.STL"/>
      </geometry>
    </visual>
    <collision>
      <origin rpy="0 0 0" xyz="-11.5 1 -13.75"/>
      <geometry>
        <mesh filename="file:///home/andrew/roboarm/rviz2_ws/src/roboarm/install/roboarm/share/roboarm/meshes/Arm03.STL"/>
      </geometry>
    </collision>
  </link>
  <joint name="arm3_link__gb_link" type="revolute">
    <axis xyz="1 0 0"/>
    <limit effort="1000.0" lower="0" upper="3.14159" velocity="0.5"/>
    <origin rpy="3.14159 -1.571 0" xyz="5 29 -14"/>
    <parent link="arm3_link"/>
    <child link="gb_link"/>
  </joint>
  <link name="gb_link">
    <visual>
      <origin rpy="0 0 0" xyz="-14 -14 -14"/>
      <geometry>
        <mesh filename="file:///home/andrew/roboarm/rviz2_ws/src/roboarm/install/roboarm/share/roboarm/meshes/Gripperbase.STL"/>
      </geometry>
    </visual>
    <collision>
      <origin rpy="0 0 0" xyz="-14 -14 -14"/>
      <geometry>
        <mesh filename="file:///home/andrew/roboarm/rviz2_ws/src/roboarm/install/roboarm/share/roboarm/meshes/Gripperbase.STL"/>
      </geometry>
    </collision>
  </link>
</robot>

